::ffff:127.0.0.1 - - [19/Dec/2024 03:59:02] "GET / HTTP/1.1" 200 -
::ffff:127.0.0.1 - - [19/Dec/2024 03:59:03] code 404, message File not found
::ffff:127.0.0.1 - - [19/Dec/2024 03:59:03] "GET /favicon.ico HTTP/1.1" 404 -
::ffff:127.0.0.1 - - [19/Dec/2024 03:59:05] "GET / HTTP/1.1" 304 -
::ffff:127.0.0.1 - - [19/Dec/2024 04:00:09] "GET / HTTP/1.1" 200 -
::ffff:127.0.0.1 - - [19/Dec/2024 04:01:28] "GET / HTTP/1.1" 200 -
::ffff:127.0.0.1 - - [19/Dec/2024 04:04:04] "GET / HTTP/1.1" 200 -
[2024-12-19 21:40:10 -0500] [9113] [INFO] Starting gunicorn 23.0.0
[2024-12-19 21:40:10 -0500] [9113] [INFO] Listening at: http://0.0.0.0:8080 (9113)
[2024-12-19 21:40:10 -0500] [9113] [INFO] Using worker: gthread
[2024-12-19 21:40:10 -0500] [9118] [INFO] Booting worker with pid: 9118
[2024-12-19 21:40:10 -0500] [9119] [INFO] Booting worker with pid: 9119
[2024-12-19 21:40:10 -0500] [9118] [ERROR] Exception in worker process
Traceback (most recent call last):
  File "/data/data/com.termux/files/usr/lib/python3.12/site-packages/gunicorn/arbiter.py", line 608, in spawn_worker
    worker.init_process()
  File "/data/data/com.termux/files/usr/lib/python3.12/site-packages/gunicorn/workers/gthread.py", line 94, in init_process
    super().init_process()
  File "/data/data/com.termux/files/usr/lib/python3.12/site-packages/gunicorn/workers/base.py", line 135, in init_process
    self.load_wsgi()
  File "/data/data/com.termux/files/usr/lib/python3.12/site-packages/gunicorn/workers/base.py", line 147, in load_wsgi
    self.wsgi = self.app.wsgi()
                ^^^^^^^^^^^^^^^
  File "/data/data/com.termux/files/usr/lib/python3.12/site-packages/gunicorn/app/base.py", line 66, in wsgi
    self.callable = self.load()
                    ^^^^^^^^^^^
  File "/data/data/com.termux/files/usr/lib/python3.12/site-packages/gunicorn/app/wsgiapp.py", line 57, in load
    return self.load_wsgiapp()
           ^^^^^^^^^^^^^^^^^^^
  File "/data/data/com.termux/files/usr/lib/python3.12/site-packages/gunicorn/app/wsgiapp.py", line 47, in load_wsgiapp
    return util.import_app(self.app_uri)
           ^^^^^^^^^^^^^^^^^^^^^^^^^^^^^
  File "/data/data/com.termux/files/usr/lib/python3.12/site-packages/gunicorn/util.py", line 370, in import_app
    mod = importlib.import_module(module)
          ^^^^^^^^^^^^^^^^^^^^^^^^^^^^^^^
  File "/data/data/com.termux/files/usr/lib/python3.12/importlib/__init__.py", line 90, in import_module
    return _bootstrap._gcd_import(name[level:], package, level)
           ^^^^^^^^^^^^^^^^^^^^^^^^^^^^^^^^^^^^^^^^^^^^^^^^^^^^
  File "<frozen importlib._bootstrap>", line 1387, in _gcd_import
  File "<frozen importlib._bootstrap>", line 1360, in _find_and_load
  File "<frozen importlib._bootstrap>", line 1324, in _find_and_load_unlocked
ModuleNotFoundError: No module named 'app'
[2024-12-19 21:40:10 -0500] [9118] [INFO] Worker exiting (pid: 9118)
[2024-12-19 21:40:10 -0500] [9119] [ERROR] Exception in worker process
Traceback (most recent call last):
  File "/data/data/com.termux/files/usr/lib/python3.12/site-packages/gunicorn/arbiter.py", line 608, in spawn_worker
    worker.init_process()
  File "/data/data/com.termux/files/usr/lib/python3.12/site-packages/gunicorn/workers/gthread.py", line 94, in init_process
    super().init_process()
  File "/data/data/com.termux/files/usr/lib/python3.12/site-packages/gunicorn/workers/base.py", line 135, in init_process
    self.load_wsgi()
  File "/data/data/com.termux/files/usr/lib/python3.12/site-packages/gunicorn/workers/base.py", line 147, in load_wsgi
    self.wsgi = self.app.wsgi()
                ^^^^^^^^^^^^^^^
  File "/data/data/com.termux/files/usr/lib/python3.12/site-packages/gunicorn/app/base.py", line 66, in wsgi
    self.callable = self.load()
                    ^^^^^^^^^^^
  File "/data/data/com.termux/files/usr/lib/python3.12/site-packages/gunicorn/app/wsgiapp.py", line 57, in load
    return self.load_wsgiapp()
           ^^^^^^^^^^^^^^^^^^^
  File "/data/data/com.termux/files/usr/lib/python3.12/site-packages/gunicorn/app/wsgiapp.py", line 47, in load_wsgiapp
    return util.import_app(self.app_uri)
           ^^^^^^^^^^^^^^^^^^^^^^^^^^^^^
  File "/data/data/com.termux/files/usr/lib/python3.12/site-packages/gunicorn/util.py", line 370, in import_app
    mod = importlib.import_module(module)
          ^^^^^^^^^^^^^^^^^^^^^^^^^^^^^^^
  File "/data/data/com.termux/files/usr/lib/python3.12/importlib/__init__.py", line 90, in import_module
    return _bootstrap._gcd_import(name[level:], package, level)
           ^^^^^^^^^^^^^^^^^^^^^^^^^^^^^^^^^^^^^^^^^^^^^^^^^^^^
  File "<frozen importlib._bootstrap>", line 1387, in _gcd_import
  File "<frozen importlib._bootstrap>", line 1360, in _find_and_load
  File "<frozen importlib._bootstrap>", line 1324, in _find_and_load_unlocked
ModuleNotFoundError: No module named 'app'
[2024-12-19 21:40:11 -0500] [9119] [INFO] Worker exiting (pid: 9119)
[2024-12-19 21:40:11 -0500] [9113] [ERROR] Worker (pid:9118) exited with code 3
[2024-12-19 21:40:11 -0500] [9113] [ERROR] Worker (pid:9119) was sent SIGTERM!
[2024-12-19 21:40:11 -0500] [9113] [ERROR] Shutting down: Master
[2024-12-19 21:40:11 -0500] [9113] [ERROR] Reason: Worker failed to boot.
